# 47장 - 에러 처리

## 에러 처리의 필요성

- 에러가 발생하지 않는 코드ㅏ를 작성하는 것은 불가능
- 에러에 대처하지 않고 방치하면 프로그램 강제 종료

```jsx
console.log("[Start]");

foo(); //	ReferenceError:	foo	is	not	defined
// 발생한 에러를 방치하면 프로그램은 강제 종료된다.

// 에러에 의해 프로그램이 강제 종료되어 아래 코드는 실행되지 않는다.
console.log("[End]");
```

- try … catch 문을 사용해 발생한 에러에 대응하면 프로그램 강제 종료 X

```jsx
console.log("[Start]");
try {
  foo();
} catch (error) {
  console.error("[에러 발생]", error);
  // [에러 발생]	ReferenceError:	foo	is	not	defined
}

// 발생한 에러에 적절한 대응을 하면 프로그램이 강제 종료되지 않는다.
console.log("[End]");
```

- 직접적으로 에러를 발생하지는 않는 예외적인 상황에 적절하게 대응하지 않으면 에러로 이어짐

```jsx
// DOM에 button 요소가 존재하지 않으면 querySelector 메서드는 에러를 발생시키지 않고 null을 반환한다.
const $button = document.querySelector("button"); // null
$button.classList.add("disabled");
// TypeError :	Cannot	read	property	'classList'	of	null
```

- querySelector 메서드는 인수로 전달한 CSS 선택자 문자열로 DOM에서 요소 노드를 찾을 수 없는 경우 에러 X, null 반환
- if문, 단축 평가, 옵셔널 체이닝 연산자 ?. 을 사용하지 않으면 에러 날 가능성 큼

```jsx
// DOM에 button 요소가 존재하는 경우 querySelector 메서드는 에러를 발생시키지 않고 null을 반환한다.
const $button = document.querySelector("button"); // null
$button?.classList.add("disabled");
```

- 이처럼 대응하지 않으면 강제 종료
- 에러나 예외적인 상황은 너무 다양해서 조치 없이 프로그램이 강제 종료되면 원인 파악 및 대응이 어려움
- 항상 에러나 예외적인 상황이 발생할 수 있다고 생각하고 코딩해라

## try … catch … finally 문

- 에러 처리 구현 방법
  - quertSelector, Array#find 메서드 사용
    - 예외적인 상황 발생 시 null 또는 -1 반환
    - if문이나 단축평가, 옵셔널 체이닝 연산자를 통해 확인해서 처리
  - 에러 처리코드를 미리 등록하고 에러 발생 시 에러 처리 코드로 점프
- try … catch … finally 문 사용 (에러 처리)
  - finally, catch 문 생략 가능

```jsx
try {
  // 실행할 코드
} catch (err) {
  // try 코드 블록에서 에러 발생 시 실행
  // err에는 try에서 발생한 Error 객체 전달
} finally {
  // 에러 발생과 상관없이 반드시 한 번 실행
}
```

- try … catch … finally 문으로 에러 처리 시 강제 종료 X

```jsx
console.log("[Start]");

try {
  foo();
} catch (err) {
  console.log(err);
} finally {
  console.log("finally");
}

console.log("[End]");
```

## Error 객체

- Error 생성자 함수는 에러 객체 생성하여 상세히 설명하는 에러 메시지 인수로 전달
- 에러 객체는 message, stack 프로퍼티를 갖는다
- message 프로퍼티는 Error 생성자 함수에 인수로 전달한 에러 메시지
- stack 프로퍼티는 에러를 발생시킨 콜스택의 호출 정보 (디버깅 목적으로 사용)

| 생성자 함수    | 인스턴스                                                                       |
| -------------- | ------------------------------------------------------------------------------ |
| Error          | 일반적 에러 객체                                                               |
| SyntaxError    | 자바스크립트 문법에 맞지 않을 때 발생하는 에러 객체                            |
| ReferenceError | 참조할 수 없는 식별자를 참초했을 때 발생하는 에러 객체                         |
| TypeError      | 피연산자 또는 인수의 데이터 타입이 유효하지 않을 때 발새아는 에러 객체         |
| RangeError     | 숫자값의 허용 범위를 벗어났을 때 발생하는 에러 객체                            |
| URIError       | encodeURI 또는 decodeURI 함수에 부적절한 인수를 전달했을 때 발생하는 에러 객체 |
| EvalError      | eval 함수에서 발생하는 에러 객체                                               |

## throw 문

- Error 생성사 함수로 에러 객체를 생성한다고 에러 발생하는 것은 X
- 즉, 에러 객체 생성과 에러 발생은 의미가 다름
- 에러를 발생시키려면 try 코드 블록에서 throw 문으로 에러 객체를 던져야 함
  - `throw 표현식;`
- 어떤 값이라도 상관 X, 일반적으로 에러 객체 지정
- 에러 던지면 catch 문의 에러 변수 생성 후 던져진 에러 객체 할당 후 catch 코드 블록 실행 시작

```jsx
try {
  throw new Error("wrong");
} catch (err) {
  console.log(err);
}
```

- 공부 잘 했는지 확인

```jsx
const repeat = (n, f) => {
  if (typeof f !== "function") throw new TypeError("f must be a function");
  for (var i = 0; i < n; i++) {
    f(i);
  }
};

try {
  repeat(2, 1);
} catch (err) {
  console.error(err);
}
```

- 정답💡
  - 외부에서 전달 받은 콜백 함수를 n번 반복 호출
  - 매개변수 f에 전달된 인수가 함수가 아니면 TypeError
  - f에 전달한 인수가 함수가 아니기 때문에 TypeError 발생

## 에러의 전파

- 호출자 방향으로 전파 (콜 스택의 아래 방향(실행 컨텍스트가 푸시되기 직전에 푸시된 실행 컨텍스트)으로 전파)

```jsx
const foo = () => {
  throw Error("foo에서 발생한 에러");
};

const bar = () => {
  foo();
};

const baz = () => {
  bar();
};

try {
  baz();
} catch (err) {
  console.error(err);
}
```

![image.png](https://prod-files-secure.s3.us-west-2.amazonaws.com/29f67a0d-cdfb-41bc-ba0a-5aa0b4aaac8a/5ed14536-0394-4d45-85d9-ca64e407fb27/image.png)

- throw된 에러를 캐치하지 않으면 호출자 방향으로 전파
- 이 때 throw된 에러를 캐치하여 적절히 대응하면 코드의 실행 흐름 복구 가능
- 주의 사항
  - 비동기 함수인 setTimeout이나 프로미스 후속 처리 메서드의 콜백 함수는 호출자가 없음
  - setTimeout이나 프로미스 후속 처리 메서드의 콜백 함수는 태스크 큐나 마이크로태스크 큐에 일시 저장되었다가 콜 스택이 비면 이벤트 루프에 의해 콜 스택으로 푸시되어 실행
  - 이 때 콜 스택에 푸시된 콜백 함수의 실행 컨텍스트는 콜 스택의 가장 하부에 존재 (에러를 전파할 호출자 존재 X)

setTimeout 참고 : https://developer.mozilla.org/ko/docs/Web/API/Window/setTimeout
